Workbook

Sheet plataformas
A1: Caracteríticas plataforma
A2: procesador | B2: RAM | C2: S.O
A3: AMD Ryzen 5 | B3: 16 | C3: Windows 11
A4: Características del procesador: | C4: AMD Ryzen 5 5500U with Radeon Graphics (2,10 GHz)
A5: Software especializado empleado:

Sheet 10A-Elementos
A1: Estado inicial | B1: 1000000000
A2: Sistema: | B2: ABCDEFGHIJ
A3: Sistema Candidato: | B3: ABCDEFGHIJ | D3: PRUEBAS BIPARTICIONES | J3: PRUEBAS 3-PARTICIONES | P3: PRUEBAS 4-PARTICIONES | V3: PRUEBAS 5-PARTICIONES
B4: Subsistema | D4: QNodes | G4: Geometric | J4: QNodes | M4: Geometric | P4: QNodes | S4: Geometric | V4: QNodes | Y4: Geometric
A5: #Prueba | B5: Alcance o Purview (t+1) | C5: Mecanismo(t) | D5: Partición | E5: Pérdida | F5: Tiempo (seg) | G5: Partición | H5: Pérdida | I5: Tiempo | J5: Partición | K5: Pérdida | L5: Tiempo (seg) | M5: Partición | N5: Pérdida | O5: Tiempo | P5: Partición | Q5: Pérdida | R5: Tiempo | S5: Partición | T5: Pérdida | U5: Tiempo | V5: Partición | W5: Pérdida | X5: Tiempo (seg) | Y5: Partición | Z5: Pérdida | AA5: Tiempo
A6: =ROW(A1) -> 1 | B6: ABCDEFGHIJ | C6: ABCDEFGHIJ | D6: ⎛ I ⎞⎛ A,B,C,D,E,F,G,H,J ⎞ ⎝ ∅ ⎠⎝ a,b,c,d,e,f,g,h,i,j ⎠ | E6: 0.4805 | F6: 0.9596 | G6: ⎛ A,B,C,D,E,F,G,H,J ⎞⎛ I ⎞ ⎝ a,b,c,d,e,f,g,h,i,j ⎠⎝ ∅ ⎠ | H6: 0.472656 | I6: 1.5361 | J6: | H || A,B,C,D,F,G,I,J || E | --------------------------------- | ∅ || a,b,c,d,e,f,g,h,i,j || ∅ | | K6: 1.0273 | L6: 1.1154 | M6: | A,B,D,E,F,G,H,J || C || I | --------------------------------- | a,b,c,d,e,f,g,h,i,j || ∅ || ∅ | | N6: 0.953125 | O6: 2.0904 | P6: | E,G,H || I || ∅ || A,B,C,D,F,J | ------------------------------------ | a,i || ∅ || b || c,d,e,f,g,h,j | | Q6: 3.3828 | R6: 0.6364 | S6: | B,D,E,F,G,H,J || A || C || I | -------------------------------------- | a,b,c,d,e,f,g,h,i,j || ∅ || ∅ || ∅ | | T6: 1.433594 | U6: 4.8415 | V6: | G,H || B,C,D,E || ∅ || A,F,J || I | --------------------------------------- | a,i || d,f,g || b || c,e,h,j || ∅ | | W6: 4.3984 | X6: 0.6302 | Y6: | B,D,E,F,G,J || A || C || H || I | ----------------------------------------- | a,b,c,d,e,f,g,h,j || ∅ || ∅ || i || ∅ | | Z6: 1.917969 | AA6: 7.9711
A7: =ROW(A2) -> 2 | B7: ABCDEFGHIJ | C7: ABCDEFGHI | D7: ⎛ G ⎞⎛ A,B,C,D,E,F,H,I,J ⎞ ⎝ ∅ ⎠⎝ a,b,c,d,e,f,g,h,i ⎠ | E7: 0.0059 | F7: 0.67 | G7: ⎛ A,B,C,D,E,F,H,I,J ⎞⎛ G ⎞ ⎝ a,b,c,d,e,f,g,h,i ⎠⎝ ∅ ⎠ | H7: 0.004883 | I7: 0.7382 | J7: | ∅ || C,G,J || A,B,D,E,F,H,I | --------------------------------- | e || ∅ || a,b,c,d,f,g,h,i | | K7: 1.0303 | L7: 0.9432 | M7: | A,B,C,D,E,F,H,I || G || J | ------------------------------- | a,b,c,d,e,f,g,h,i || ∅ || ∅ | | N7: 0.010742 | O7: 0.9255 | P7: | ∅ || B || D,E,F,H,I || A,C,G,J | ---------------------------------------- | d || ∅ || a,b,c,e,f,g,h,i || ∅ | | Q7: 1.0615 | R7: 0.527 | S7: | A,B,D,E,F,H,I || C || G || J | ------------------------------------ | a,b,c,d,e,f,g,h,i || ∅ || ∅ || ∅ | | T7: 0.030273 | U7: 1.6895 | V7: | F || I || ∅ || A,C,G,J || B,D,E,H | --------------------------------------------- | ∅ || ∅ || b || ∅ || a,c,d,e,f,g,h,i | | W7: 1.334 | X7: 0.6407 | Y7: | B,D,E,F,H,I || A || C || G || J | ----------------------------------------- | a,b,c,d,e,f,g,h,i || ∅ || ∅ || ∅ || ∅ | | Z7: 0.049805 | AA7: 2.3119
A8: =ROW(A3) -> 3 | B8: ABCDEFGHIJ | C8: BCDEFGHIJ | D8: ⎛ G ⎞⎛ A,B,C,D,E,F,H,I,J ⎞ ⎝ ∅ ⎠⎝ b,c,d,e,f,g,h,i,j ⎠ | E8: 0.0068 | F8: 0.6079 | G8: ⎛ A,B,C,D,E,F,H,I,J ⎞⎛ G ⎞ ⎝ b,c,d,e,f,g,h,i,j ⎠⎝ ∅ ⎠ | H8: 0.004883 | I8: 0.6779 | J8: | G || A || B,C,D,E,F,H,I,J | ------------------------------- | ∅ || ∅ || b,c,d,e,f,g,h,i,j | | K8: 0.4854 | L8: 0.7711 | M8: | A,B,C,D,E,H,I,J || F || G | ------------------------------- | b,c,d,e,f,g,h,i,j || ∅ || ∅ | | N8: 0.011719 | O8: 1.0507 | P8: | E,F,G,I || ∅ || A,B,D,H,J || C | ---------------------------------------- | ∅ || b || c,d,e,f,g,h,i,j || ∅ | | Q8: 1.4805 | R8: 0.53 | S8: | A,B,C,D,E,I,J || F || G || H | ------------------------------------ | b,c,d,e,f,g,h,i,j || ∅ || ∅ || ∅ | | T8: 0.023438 | U8: 1.6948 | V8: | F || G || A,H,I || B,C,D,E,J || ∅ | --------------------------------------- | i || ∅ || j || b,c,d,f,g,h || e | | W8: 2.0576 | X8: 0.6446 | Y8: | A,C,D,E,I,J || B || F || G || H | ----------------------------------------- | b,c,d,e,f,g,h,i,j || ∅ || ∅ || ∅ || ∅ | | Z8: 0.035156 | AA8: 2.3142
A9: =ROW(A4) -> 4 | B9: ABCDEFGHIJ | C9: BCDEFGHI | D9: ⎛ H ⎞⎛ A,B,C,D,E,F,G,I,J ⎞ ⎝ ∅ ⎠⎝ b,c,d,e,f,g,h,i ⎠ | E9: 0.0117 | F9: 0.5066 | G9: ⎛ A,B,C,D,E,F,G,I,J ⎞⎛ H ⎞ ⎝ b,c,d,e,f,g,h,i ⎠⎝ ∅ ⎠ | H9: 0.011719 | I9: 0.3059 | J9: | ∅ || A,B,C,D,E,G,J || F,H,I | --------------------------------- | c,h || b,d,e,f,g,i || ∅ | | K9: 0.6709 | L9: 0.7876 | M9: | A,C,D,E,F,G,I,J || B || H | ----------------------------- | b,c,d,e,f,g,h,i || ∅ || ∅ | | N9: 0.023438 | O9: 0.356 | P9: | I || A,B || D,E,F,G,H,J || C | -------------------------------- | b || i || c,d,e,f,g,h || ∅ | | Q9: 0.7637 | R9: 0.415 | S9: | A || C,D,E,F,G,I,J || B || H | ---------------------------------- | ∅ || b,c,d,e,f,g,h,i || ∅ || ∅ | | T9: 0.042969 | U9: 0.5671 | V9: | H || A || G || B,C,D,E,F,J || I | ------------------------------------- | ∅ || ∅ || c,h || b,d,e,f,g,i || ∅ | | W9: 0.8594 | X9: 0.6133 | Y9: | A || C,D,E,F,G,J || B || H || I | --------------------------------------- | ∅ || b,c,d,e,f,g,h,i || ∅ || ∅ || ∅ | | Z9: 0.070312 | AA9: 0.7631
A10: =ROW(A5) -> 5 | B10: ABCDEFGHIJ | C10: ABDEGHJ | D10: ⎛ J ⎞⎛ A,B,C,D,E,F,G,H,I ⎞ ⎝ ∅ ⎠⎝ a,b,d,e,g,h,i,j ⎠ | E10: 0.0068 | F10: 0.4252 | G10: ⎛ A,B,C,D,E,F,G,H,I ⎞⎛ J ⎞ ⎝ a,b,d,e,g,h,j ⎠⎝ ∅ ⎠ | H10: 0.005859 | I10: 0.2202 | J10: | B,C,D,G,H,I || A,E,F || J | ----------------------------- | a,d,g,h || b,e,j || ∅ | | K10: 0.623 | L10: 0.73 | M10: | A,B,D,E,F,G,H,I || C || J | ----------------------------- | a,b,d,e,g,h,j || ∅ || ∅ | | N10: 0.025391 | O10: 0.2468 | P10: | C,F,H,I || A,B,G || ∅ || D,E,J | ------------------------------------ | a || e,g,h,j || b || d | | Q10: 0.7832 | R10: 0.2704 | S10: | A,B,D,E,F,G,H || C || I || J | -------------------------------- | a,b,d,e,g,h,j || ∅ || ∅ || ∅ | | T10: 0.052734 | U10: 0.2279 | V10: | C,F,G,I || A,J || ∅ || B,E || D,H | ------------------------------------- | a || g,j || b || d || e,h | | W10: 0.8086 | X10: 0.449 | Y10: | B,D,E,F,G,H || A || C || I || J | ------------------------------------- | a,b,d,e,g,h,j || ∅ || ∅ || ∅ || ∅ | | Z10: 0.158203 | AA10: 0.2534
A11: =ROW(A6) -> 6 | B11: ABCDEFGHIJ | C11: ACEGI | D11: ⎛ E ⎞⎛ A,B,C,D,F,G,H,I,J ⎞ ⎝ ∅ ⎠⎝ a,c,e,g,i ⎠ | E11: 0.0244 | F11: 0.2577 | G11: ⎛ A,B,C,D,F,G,H,I,J ⎞⎛ E ⎞ ⎝ a,c,e,g,i ⎠⎝ ∅ ⎠ | H11: 0.015625 | I11: 0.0399 | J11: | J || B || A,C,D,E,F,G,H,I | ----------------------------- | ∅ || ∅ || a,c,e,g,i | | K11: 0.1113 | L11: 0.3657 | M11: | A,B,C,D,G,H,I,J || E || F | ----------------------------- | a,c,e,g,i || ∅ || ∅ | | N11: 0.040039 | O11: 0.0527 | P11: | A,C,E,I || B,D,F,H || J || G | -------------------------------- | a,c || e,g,i || ∅ || ∅ | | Q11: 0.4346 | R11: 0.3611 | S11: | A,B,C,D,G,H,I || E || F || J | -------------------------------- | a,c,e,g,i || ∅ || ∅ || ∅ | | T11: 0.077148 | U11: 0.0414 | V11: | C || A,B,D,E,J || G,H || I || F | ----------------------------------- | a || i || c,g || e || ∅ | | W11: 0.54 | X11: 0.4338 | Y11: | B,C,D,G,H,I || A || E || F || J | ----------------------------------- | a,c,e,g,i || ∅ || ∅ || ∅ || ∅ | | Z11: 0.12793 | AA11: 0.0574
A12: =ROW(A7) -> 7 | B12: ABCDEFGHIJ | C12: BDFHJ | D12: ⎛ I ⎞⎛ A,B,C,D,E,F,G,H,J ⎞ ⎝ ∅ ⎠⎝ b,d,f,h,j ⎠ | E12: 0.0117 | F12: 0.2377 | G12: ⎛ A,B,C,D,E,F,G,H,J ⎞⎛ I ⎞ ⎝ b,d,f,h,j ⎠⎝ ∅ ⎠ | H12: 0.003906 | I12: 0.051 | J12: | C,F || A,B,D,E,G,H,J || I | ----------------------------- | ∅ || b,d,f,h,j || ∅ | | K12: 0.04 | L12: 0.4699 | M12: | A,B,D,E,F,G,H,J || C || I | ----------------------------- | b,d,f,h,j || ∅ || ∅ | | N12: 0.015625 | O12: 0.0395 | P12: | B,E,G,H,J || A,F || D || C,I | -------------------------------- | b,d,f,h,j || ∅ || ∅ || ∅ | | Q12: 0.1211 | R12: 0.3309 | S12: | A || B,D,E,F,G,H,J || C || I | -------------------------------- | ∅ || b,d,f,h,j || ∅ || ∅ | | T12: 0.035156 | U12: 0.0723 | V12: | E,F,H || A,B,C,J || D || G || I | ----------------------------------- | b,f,j || h || d || ∅ || ∅ | | W12: 0.2646 | X12: 0.321 | Y12: | A || B,D,E,G,H,J || C || F || I | ----------------------------------- | ∅ || b,d,f,h,j || ∅ || ∅ || ∅ | | Z12: 0.05957 | AA12: 0.1001
A13: =ROW(A8) -> 8 | B13: ABCDEFGHI | C13: ABCDEFGHIJ | D13: ⎛ I ⎞⎛ A,B,C,D,E,F,G,H ⎞ ⎝ ∅ ⎠⎝ a,b,c,d,e,f,g,h,i,j ⎠ | E13: 0.4805 | F13: 0.7161 | G13: ⎛ A,B,C,D,E,F,G,H ⎞⎛ I ⎞ ⎝ a,b,c,d,e,f,g,h,i,j ⎠⎝ ∅ ⎠ | H13: 0.472656 | I13: 1.5776 | J13: | D,E,F,H || A,B,C,G,I || ∅ | ------------------------------------- | a,c,d,e,f,g,h,i || j || b | | K13: 2.8574 | L13: 0.8058 | M13: | A,B,D,E,F,G,H || C || I | --------------------------------- | a,b,c,d,e,f,g,h,i,j || ∅ || ∅ | | N13: 0.953125 | O13: 2.202 | P13: | G || A,B,C,D,E,F,H || ∅ || I | ------------------------------------ | ∅ || a,c,d,e,f,g,h,i,j || b || ∅ | | Q13: 2.4678 | R13: 0.5645 | S13: | B,D,E,F,G,H || A || C || I | -------------------------------------- | a,b,c,d,e,f,g,h,i,j || ∅ || ∅ || ∅ | | T13: 1.433594 | U13: 5.6584 | V13: | E,G,H || B || C,I || A,D || F | --------------------------------------- | a,e,f,i || ∅ || j || b,c,g,h || d | | W13: 3.9355 | X13: 0.5584 | Y13: | B,D,E,F,G || A || C || H || I | ----------------------------------------- | a,b,c,d,e,f,g,h,j || ∅ || ∅ || i || ∅ | | Z13: 1.917969 | AA13: 7.7408
A14: =ROW(A9) -> 9 | B14: ABCDEFGHI | C14: ABCDEFGHI | D14: ⎛ G ⎞⎛ A,B,C,D,E,F,H,I ⎞ ⎝ ∅ ⎠⎝ a,b,c,d,e,f,g,h,i ⎠ | E14: 0.0195 | F14: 0.5444 | G14: ⎛ A,B,C,D,E,F,H,I ⎞⎛ G ⎞ ⎝ a,b,c,d,e,f,g,h,i ⎠⎝ ∅ ⎠ | H14: 0.004883 | I14: 0.9293 | J14: | G || B || A,C,D,E,F,H,I | ------------------------------- | ∅ || ∅ || a,b,c,d,e,f,g,h,i | | K14: 0.5166 | L14: 0.7133 | M14: | A,B,D,E,F,H,I || C || G | ------------------------------- | a,b,c,d,e,f,g,h,i || ∅ || ∅ | | N14: 0.024414 | O14: 1.082 | P14: | A,G || B || D,E,F,H || C,I | ---------------------------------------- | ∅ || ∅ || a,b,c,d,e,f,g,h,i || ∅ | | Q14: 0.583 | R14: 0.4859 | S14: | B,D,E,F,H,I || A || C || G | ------------------------------------ | a,b,c,d,e,f,g,h,i || ∅ || ∅ || ∅ | | T14: 0.043945 | U14: 1.8993 | V14: | I || ∅ || H || A,C,G || B,D,E,F | ------------------------------------------- | ∅ || h || ∅ || ∅ || a,b,c,d,e,f,g,i | | W14: 1.083 | X14: 0.554 | Y14: | B,D,E,F,H || A || C || G || I | ----------------------------------------- | a,b,c,d,e,f,g,h,i || ∅ || ∅ || ∅ || ∅ | | Z14: 0.071289 | AA14: 2.1902
A15: =ROW(A10) -> 10 | B15: ABCDEFGHI | C15: BCDEFGHIJ | D15: ⎛ G ⎞⎛ A,B,C,D,E,F,H,I ⎞ ⎝ ∅ ⎠⎝ b,c,d,e,f,g,h,i,j ⎠ | E15: 0.0068 | F15: 0.456 | G15: ⎛ A,B,C,D,E,F,H,I ⎞⎛ G ⎞ ⎝ b,c,d,e,f,g,h,i,j ⎠⎝ ∅ ⎠ | H15: 0.004883 | I15: 0.634 | J15: | F,G,H || A,B,C,D,I || E | ----------------------------------- | ∅ || b,c,d,e,f,g,h,i,j || ∅ | | K15: 0.0391 | L15: 0.7383 | M15: | A,B,C,D,E,H,I || F || G | ------------------------------- | b,c,d,e,f,g,h,i,j || ∅ || ∅ | | N15: 0.011719 | O15: 0.8582 | P15: | ∅ || B,C,D,E,H,I || A,F || G | ------------------------------------ | b || d,f,g,h || c,e,i,j || ∅ | | Q15: 1.5986 | R15: 0.5174 | S15: | A,B,C,D,E,I || F || G || H | ------------------------------------ | b,c,d,e,f,g,h,i,j || ∅ || ∅ || ∅ | | T15: 0.023438 | U15: 1.4871 | V15: | ∅ || A,C,E,I || B,F,G || D,H || ∅ | --------------------------------------- | c || f,g,h,j || ∅ || b,d,i || e | | W15: 1.6484 | X15: 0.5825 | Y15: | A,C,D,E,I || B || F || G || H | ----------------------------------------- | b,c,d,e,f,g,h,i,j || ∅ || ∅ || ∅ || ∅ | | Z15: 0.035156 | AA15: 2.2531
A16: =ROW(A11) -> 11 | B16: ABCDEFGHI | C16: BCDEFGHI | D16: ⎛ H ⎞⎛ A,B,C,D,E,F,G,I ⎞ ⎝ ∅ ⎠⎝ b,c,d,e,f,g,h,i ⎠ | E16: 0.0117 | F16: 0.366 | G16: ⎛ A,B,C,D,E,F,G,I ⎞⎛ H ⎞ ⎝ b,c,d,e,f,g,h,i ⎠⎝ ∅ ⎠ | H16: 0.011719 | I16: 0.3313 | J16: | F || A,B,C,D,E,G,I || H | ----------------------------- | ∅ || b,d,e,f,g,i || c,h | | K16: 0.5107 | L16: 0.5766 | M16: | A,C,D,E,F,G,I || B || H | ----------------------------- | b,c,d,e,f,g,h,i || ∅ || ∅ | | N16: 0.023438 | O16: 0.3762 | P16: | C,D,E,G,I || A || ∅ || B,F,H | ---------------------------------- | b,e,f,g,h,i || ∅ || c || d | | Q16: 0.666 | R16: 0.4595 | S16: | A || C,D,E,F,G,I || B || H | ---------------------------------- | ∅ || b,c,d,e,f,g,h,i || ∅ || ∅ | | T16: 0.042969 | U16: 0.5741 | V16: | ∅ || A || I || B,C,D,F,G,H || E | ----------------------------------- | b || i || ∅ || c,d,e,f,g,h || ∅ | | W16: 0.7949 | X16: 0.5314 | Y16: | A || C,D,E,F,G || B || H || I | --------------------------------------- | ∅ || b,c,d,e,f,g,h,i || ∅ || ∅ || ∅ | | Z16: 0.070312 | AA16: 0.7777
A17: =ROW(A12) -> 12 | B17: ABCDEFGHI | C17: ABDEGHJ | D17: ⎛ C ⎞⎛ A,B,D,E,F,G,H,I ⎞ ⎝ ∅ ⎠⎝ a,b,d,e,g,h,j ⎠ | E17: 0.0273 | F17: 0.3018 | G17: ⎛ A,B,D,E,F,G,H,I ⎞⎛ C ⎞ ⎝ a,b,d,e,g,h,j ⎠⎝ ∅ ⎠ | H17: 0.019531 | I17: 0.2098 | J17: | C || A,B,D,E,G,I || F,H | --------------------------- | ∅ || a,d,g,h,j || b,e | | K17: 0.5352 | L17: 0.6536 | M17: | A,B,D,E,F,G,H || C || I | --------------------------- | a,b,d,e,g,h,j || ∅ || ∅ | | N17: 0.046875 | O17: 0.2229 | P17: | C,D,E,G,I || A || ∅ || B,F,H | ---------------------------------- | b,e,f,g,h,i || ∅ || c || d | | Q17: 0.666 | R17: 0.4663 | S17: | B,D,E,F,G,H || A || C || I | -------------------------------- | a,b,d,e,g,h,j || ∅ || ∅ || ∅ | | T17: 0.152344 | U17: 0.2633 | V17: | H || B || I || C,D,F,G || A,E | ------------------------------------- | ∅ || ∅ || ∅ || a,d,g || b,e,h,j | | W17: 0.6914 | X17: 0.4364 | Y17: | B,D,F,G,H || A || C || E || I | ------------------------------------- | a,b,d,e,g,h,j || ∅ || ∅ || ∅ || ∅ | | Z17: 0.261719 | AA17: 0.1985
... A54: =ROW(A49) -> 49 | B54: BDFHJ | C54: BDFHJ | D54: ⎛ F ⎞⎛ B,D,H,J ⎞ ⎝ ∅ ⎠⎝ b,d,f,h,j ⎠ | E54: 0.0254 | F54: 0.0551 | G54: ⎛ B,D,H,J ⎞⎛ F ⎞ ⎝ b,d,f,h,j ⎠⎝ ∅ ⎠ | H54: 0.024414 | I54: 0.0804 | J54: | H || B,F,J || D | ----------------------- | b,j || h || d,f | | K54: 0.1074 | L54: 0.0659 | M54: | B,D,H || F || J | ----------------------- | b,d,f,h,j || ∅ || ∅ | | N54: 0.049805 | O54: 0.0878 | P54: | H || B,F,J || D || ∅ | -------------------------- | b,j || h || d || f | | Q54: 0.125 | R54: 0.0625 | S54: | B,D,H || F || ∅ || J | -------------------------- | b,d,f,h || ∅ || j || ∅ | | T54: 0.081055 | U54: 0.093 | V54: | H || B || D || ∅ || F,J | ----------------------------- | b,j || ∅ || d || f || h | | W54: 0.1465 | X54: 0.1263 | Y54: | B,D || F || H || ∅ || J | ------------------------------- | b,d,f,h || ∅ || ∅ || j || ∅ | | Z54: 0.092773 | AA54: 0.1062

Sheet 15B-Elementos
A1: Estado inicial | B1: 100000000000000
A2: Sistema: | B2: ABCDEFGHIJKLMNO
A3: Sistema Candidato: | B3: ABCDEFGHIJKLMNO | D3: PRUEBAS BIPARTICIONES | J3: PRUEBAS 3-PARTICIONES | P3: PRUEBAS 4-PARTICIONES | V3: PRUEBAS 5-PARTICIONES
B4: Subsistema | D4: QNodes | G4: Geometric | J4: QNodes | M4: Geometric | P4: QNodes | S4: Geometric | V4: QNodes | Y4: Geometric
A5: #Prueba | B5: Alcance o Purview (t+1) | C5: Mecanismo(t) | D5: Partición | E5: Pérdida | F5: Tiempo | G5: Partición | H5: Pérdida | I5: Tiempo | J5: Partición | K5: Pérdida | L5: Tiempo | M5: Partición | N5: Pérdida | O5: Tiempo | P5: Partición | Q5: Pérdida | R5: Tiempo | S5: Partición | T5: Pérdida | U5: Tiempo | V5: Partición | W5: Pérdida | X5: Tiempo | Y5: Partición | Z5: Pérdida | AA5: Tiempo
A6: =ROW(A1) -> 1 | B6: ABCDEFGHIJKLMNO | C6: ABCDEFGHIJKLMNO | D6: ⎛ ∅ ⎞⎛ A,B,C,D,E,F,G,H,I,J,K,L,M,N,O ⎞ ⎝ b ⎠⎝ a,c,d,e,f,g,h,i,j,k,l,m,n,o ⎠ | E6: 0 | F6: 0.056 | G6: ⎛ A ⎞⎛ B,C,D,E,F,G,H,I,J,K,L,M,N,O ⎞ ⎝ b,d,f,h,j,l,n ⎠⎝ a,c,e,g,i,k,m,o ⎠ | H6: 0.071169 | I6: 30.0536 | J6: | A,E,F,H || B,C,D,G,I,J,K,L,M,N,O || ∅ | ----------------------------------------------- | a,e,f,m,n || b,c,g,h,j,k,o || d,i,l | | K6: 0.2308 | L6: 3.5663 | M6: | ∅ || A,B,C,D,E,F,G,H,I,J,K,L,M,N,O || ∅ | ------------------------------------------------- | a || b,c,d,e,f,g,h,i,l,o || j,k,m,n | | N6: 0 | O6: 22.4467 | P6: | ∅ || B || F,O || A,C,D,E,G,H,I,J,K,L,M,N | -------------------------------------------------- | f,i,n || h || b,d,l || a,c,e,g,j,k,m,o | | Q6: 0.2172 | R6: 4.2349 | S6: | A || B,D,E,F,G,H,I,J,K,L,M,N,O || C || ∅ | -------------------------------------------------- | ∅ || a,b,c,d,e,f,h,i,j,l,m || ∅ || g,k,n,o | | T6: 0.008518 | U6: 30.5297 | V6: | ∅ || B,L,O || ∅ || A,C,D,E,F,G,H,I,J,K,N || M | ----------------------------------------------------- | a,m || h,o || l || b,c,f,g,i,j,k,n || d,e | | W6: 0.2452 | X6: 4.0002 | Y6: | A || ∅ || B,C,D,E,F,G,H,I,J,K,L,M,N,O || ∅ || ∅ | ------------------------------------------------------- | ∅ || a || b,c,d,e,f,g,h,i,j,o || k || l,m,n | | Z6: 0.004263 | AA6: 31.1088
A7: =ROW(A2) -> 2 | B7: ABCDEFGHIJKLMNO | C7: ABCDEFGHIJKLMN | D7: ⎛ ∅ ⎞⎛ A,B,C,D,E,F,G,H,I,J,K,L,M,N,O ⎞ ⎝ b ⎠⎝ a,c,d,e,f,g,h,i,j,k,l,m,n ⎠ | E7: 0 | F7: 0.0376 | G7: ⎛ A,C,D,E,F,G,H,I,J,K,L,M,N,O ⎞⎛ B ⎞ ⎝ b,d,f,h,j,l,n ⎠⎝ a,c,e,g,i,k,m ⎠ | H7: 0.0806 | I7: 30.0702 | J7: | ∅ || A,B,C,D,E,F,G,H,I,J,K,L,M,N,O || ∅ | ----------------------------------------------------- | a,c,f,g,k || b,d,e,h,j,l,m || i,n | | K7: 0.2383 | L7: 2.0399 | M7: | A,B,C,D,E,F,G,H,I,J,K,L,M,N,O || ∅ || ∅ | ----------------------------------------------- | b,c,d,f,g,h,i,j,k,n || a || e,l,m | | N7: 0 | O7: 11.2993 | P7: | ∅ || A,B,C,E,F,G,H,I,J,K,O || ∅ || D,L,M,N | ---------------------------------------------- | a || d,e,f,g,h,i,j,l,m,n || b || c,k | | Q7: 0.1648 | R7: 2.3245 | S7: | ∅ || A,B,C,D,E,F,G,H,I,J,K,L,M,N,O || ∅ || ∅ | -------------------------------------------------- | a || e,f,g,h,i,j,k,l,m,n || b || c,d | | T7: 0 | U7: 17.7084 | V7: | ∅ || B,C,E,G,I,K,L,N || ∅ || A,D,F,H || J,M,O | ------------------------------------------------------- | a || c,d,e,f,h,i,j,k,l,m,n || b || g || ∅ | | W7: 0.1891 | X7: 2.636 | Y7: | A,B,C,D,E,F,G,H,I,J,K,L,M,N,O || ∅ || ∅ || ∅ || ∅ | ----------------------------------------------------- | d,e,f,g,h,i,j,k,l,m || a || b || c || n | | Z7: 0 | AA7: 23.0212
A8: =ROW(A3) -> 3 | B8: ABCDEFGHIJKLMNO | C8: BCDEFGHIJKLMNO | D8: ⎛ ∅ ⎞⎛ A,B,C,D,E,F,G,H,I,J,K,L,M,N,O ⎞ ⎝ d ⎠⎝ b,c,e,f,g,h,i,j,k,l,m,n,o ⎠ | E8: 0 | F8: 0.2932 | G8: ⎛ A,B,D,E,F,G,H,I,J,K,L,M,N,O ⎞⎛ C ⎞ ⎝ c,e,g,i,k,m,o ⎠⎝ b,d,f,h,j,l,n ⎠ | H8: 0.066363 | I8: 30.0448 | J8: | J || B,F,G,M,N || A,C,D,E,H,I,K,L,O | ----------------------------------------- | ∅ || b,d,i,j || c,e,f,g,h,k,l,m,n,o | | K8: 0.1711 | L8: 2.2594 | M8: | A,B,C,D,E,F,G,H,I,J,K,L,M,N,O || ∅ || ∅ | ----------------------------------------------- | c,d,e,f,g,h,i,j,l,o || b || k,m,n | | N8: 0 | O8: 10.2293 | P8: | ∅ || A,C,E,J,M,N || B,D,G,H,I,K,L,O || F | ---------------------------------------------- | i || e,f,m,n || b,c,g,h,j,k,o || d,l | | Q8: 0.2527 | R8: 2.215 | S8: | A,B,C,D,E,F,G,H,I,J,K,L,M,N,O || ∅ || ∅ || ∅ | -------------------------------------------------- | b,c,d,f,g,h,i,j,k,n || e || l,m || o | | T8: 0 | U8: 16.6209 | V8: | F,J,L,N,O || A,B,C,D,E,I,M || G || K || H | ------------------------------------------------- | b,d,j,l || c,e,f,g,h,i,m,n,o || k || ∅ || ∅ | | W8: 0.2646 | X8: 2.4276 | Y8: | A,B,C,D,E,F,G,H,I,J,K,L,M,N,O || ∅ || ∅ || ∅ || ∅ | ----------------------------------------------------- | c,d,e,g,h,i,j,k,l,o || b || f || m || n | | Z8: 0 | AA8: 5.8181
A9: =ROW(A4) -> 4 | B9: ABCDEFGHIJKLMNO | C9: BCDEFGHIJKLMN | D9: ⎛ ∅ ⎞⎛ A,B,C,D,E,F,G,H,I,J,K,L,M,N,O ⎞ ⎝ d ⎠⎝ b,c,e,f,g,h,i,j,k,l,m,n ⎠ | E9: 0 | F9: 0.2315 | G9: ⎛ A,B,C,D,E,F,G,H,I,J,K,L,M,N,O ⎞⎛ ∅ ⎞ ⎝ b,c,d,e,f,g,h,i,j,k,l,m ⎠⎝ n ⎠ | H9: 0 | I9: 29.2885 | J9: | ∅ || A,O || B,C,D,E,F,G,H,I,J,K,L,M,N | ------------------------------------------- | n || d,i,l || b,c,e,f,g,h,j,k,m | | K9: 0.2414 | L9: 1.577 | M9: | A,B,C,D,E,F,G,H,I,J,K,L,M,N,O || ∅ || ∅ | ------------------------------------------- | c,d,e,f,g,h,i,j,k,l,m || b || n | | N9: 0 | O9: 1.9986 | P9: | ∅ || D || E,G,J,L,N || A,B,C,F,H,I,K,M,O | ---------------------------------------------- | n || b,j || c,g,k || d,e,f,h,i,l,m | | Q9: 0.284 | R9: 1.8129 | S9: | A,B,C,D,E,F,G,H,I,J,K,L,M,N,O || ∅ || ∅ || ∅ | -------------------------------------------------- | b,c,g,h,i,j,k,l,n || d,e || f || m | | T9: 0.003906 | U9: 3.3655 | V9: | ∅ || A,C,D || E,G || N || B,F,H,I,J,K,L,M,O | ----------------------------------------------- | n || b,j || c,k || ∅ || d,e,f,g,h,i,l,m | | W9: 0.2762 | X9: 2.0749 | Y9: | A,B,C,E,F,G,H,I,J,K,L,M,N,O || ∅ || D || ∅ || ∅ | --------------------------------------------------- | b,d,e,f,g,h,i,l,m,n || c || ∅ || j || k | | Z9: 0.004231 | AA9: 5.1702
A10: =ROW(A5) -> 5 | B10: ABCDEFGHIJKLMNO | C10: ABDEGHJKMN | D10: ⎛ O ⎞⎛ A,B,C,D,E,F,G,H,I,J,K,L,M,N ⎞ ⎝ ∅ ⎠⎝ a,b,d,e,g,h,j,k,m,n ⎠ | E10: 0.0013 | F10: 2.2352 | G10: ⎛ A,B,C,E,F,G,H,I,J,K,L,M,N,O ⎞⎛ D ⎞ ⎝ a,b,d,e,g,h,j,k,m,n ⎠⎝ ∅ ⎠ | H10: 0.000761 | I10: 2.3969 | J10: | C,G,H,I,J,K,M || A,L,O || B,D,E,F,N | --------------------------------------- | e,g,m,n || a,d,h || b,j,k | Perdida mínima ( φ ) = 0,0670 | K10: 0.067 | L10: 1.0107 | M10: | A,C,E,F,G,H,I,J,K,L,M,N,O || B || D | --------------------------------------- | a,b,d,e,g,h,j,k,m,n || ∅ || ∅ | | N10: 0.001555 | O10: 3.1791 | P10: | E,H || A,K,N,O || B,C,D,F,G,I,J,M || L | ---------------------------------------------- | a,e,g,m || h || b,d,j,k,n || ∅ | | Q10: 0.0659 | R10: 1.2232 | S10: | A,C,E,F,G,H,I,J,K,M,N,O || B || D || L | ------------------------------------------ | a,b,d,e,g,h,j,k,m,n || ∅ || ∅ || ∅ | | T10: 0.003028 | U10: 17.0673 | V10: | H,N,O || A || L || D,F,G,J,M || B,C,E,I,K | --------------------------------------------- | a,g || h || k || b,d,j || e,m,n | | W10: 0.0706 | X10: 1.4831 | Y10: | K || A,B,D,E,F,G,H,I,J,L,M || C || N || O | ------------------------------------------------- | a,k,m || b,d,e,g,h,j,n || ∅ || ∅ || ∅ | | Z10: 0.01649 | AA10: 30.1593
A11: =ROW(A6) -> 6 | B11: ABCDEFGHIJKLMNO | C11: ACEGIKMO | D11: ⎛ L ⎞⎛ A,B,C,D,E,F,G,H,I,J,K,M,N,O ⎞ ⎝ ∅ ⎠⎝ a,c,e,g,i,k,m,o ⎠ | E11: 0.0044 | F11: 2.1588 | G11: ⎛ A,B,C,D,E,F,G,H,I,J,K,L,M,O ⎞⎛ N ⎞ ⎝ a,c,e,g,i,k,m,o ⎠⎝ ∅ ⎠ | H11: 0.0001 | I11: 2.4167 | J11: | A,B,C,D,E,F,G,H,I,J,K,M,N,O || L || ∅ | ------------------------------------------- | a,c,g,k,o || e,m || i | | K11: 0.0487 | L11: 0.7993 | M11: | A,B,C,D,E,F,G,H,I,J,K,L,O || M || N | --------------------------------------- | a,c,e,g,i,k,m,o || ∅ || ∅ | | N11: 0.000436 | O11: 2.821 | P11: | C,D,H,M,O || ∅ || ∅ || A,B,E,F,G,I,J,K,L,N | ---------------------------------------------- | a,g,o || k || c || e,i,m | | Q11: 0.0947 | R11: 0.7342 | S11: | A,B,C,D,E,F,G,H,I,J,K,L || M || N || O | ------------------------------------------ | a,c,e,g,i,k,m,o || ∅ || ∅ || ∅ | | T11: 0.000775 | U11: 3.316 | V11: | ∅ || ∅ || ∅ || A,B,E,F,G,H,J,K,L || C,D,I,M,N,O | --------------------------------------------------- | a || k || c || e,i,m || g,o | | W11: 0.0971 | X11: 0.9462 | Y11: | A,B,C,D,E,F,G,I,J,K,L || H || M || N || O | --------------------------------------------- | a,c,e,g,i,k,m,o || ∅ || ∅ || ∅ || ∅ | | Z11: 0.001184 | AA11: 4.289
A12: =ROW(A7) -> 7 | B12: ABCDEFGHIJKLMNO | C12: BDFHJLN | D12: ⎛ G ⎞⎛ A,B,C,D,E,F,H,I,J,K,L,M,N,O ⎞ ⎝ ∅ ⎠⎝ b,d,f,h,j,l,n ⎠ | E12: 0.0072 | F12: 2.5975 | G12: ⎛ A,B,C,D,E,F,G,H,I,J,K,M,N,O ⎞⎛ L ⎞ ⎝ b,d,f,h,j,l,n ⎠⎝ ∅ ⎠ | H12: 0.000201 | I12: 1.1813 | J12: | B,E,F,I,J,L,M,N,O || K || A,C,D,G,H | --------------------------------------- | b,f,h,j,n || ∅ || d,l | | K12: 0.0745 | L12: 0.7622 | M12: | A,B,C,D,E,F,G,I,J,K,M,N,O || H || L | --------------------------------------- | b,d,f,h,j,l,n || ∅ || ∅ | | N12: 0.000477 | O12: 1.323 | P12: | B,C,F,H,I,J,L,M,N,O || A || D || E,G,K | ------------------------------------------ | b,d,h,j,l || ∅ || ∅ || f,n | | Q12: 0.0663 | R12: 0.892 | S12: | A,B,C,D,E,G,I,J,K,M,N,O || F || H || L | ------------------------------------------ | b,d,f,h,j,l,n || ∅ || ∅ || ∅ | | T12: 0.001082 | U12: 1.4854 | V12: | C || A,E || B,D,F,G,H,I,K,M,N,O || J || L | ----------------------------------------------- | ∅ || b,j || d,h,l || f,n || ∅ | | W12: 0.1009 | X12: 1.0787 | Y12: | A,B,C,D,G,I,J,K,M,N,O || E || F || H || L | --------------------------------------------- | b,d,f,h,j,l,n || ∅ || ∅ || ∅ || ∅ | | Z12: 0.001699 | AA12: 1.8955
A13: =ROW(A8) -> 8 | B13: ABCDEFGHIJKLMN | C13: ABCDEFGHIJKLMNO | D13: ⎛ ∅ ⎞⎛ A,B,C,D,E,F,G,H,I,J,K,L,M,N ⎞ ⎝ b ⎠⎝ a,c,d,e,f,g,h,i,j,k,l,m,n,o ⎠ | E13: 0 | F13: 0.0399 | G13: ⎛ A ⎞⎛ B,C,D,E,F,G,H,I,J,K,L,M,N ⎞ ⎝ a,c,e,g,i,k,m,o ⎠⎝ b,d,f,h,j,l,n ⎠ | H13: 0.073146 | I13: 30.0111 | J13: | H || D,F,G,I || A,B,C,E,J,K,L,M,N | ----------------------------------------- | ∅ || c,g,i,k,o || a,b,d,e,f,h,j,l,m,n | | K13: 0.1963 | L13: 3.3534 | M13: | ∅ || A,B,C,D,E,F,G,H,I,J,K,L,M,N || ∅ | ----------------------------------------------- | a || b,c,d,e,f,h,i,j,l,m || g,k,n,o | | N13: 0 | O13: 19.6749 | P13: | C,H || L,M || ∅ || A,B,D,E,F,G,I,J,K,N | ---------------------------------------------- | a,f,m,n || h || e || b,c,d,g,i,j,k,l,o | | Q13: 0.1946 | R13: 3.6531 | S13: | ∅ || A,B,C,D,E,F,G,H,I,J,K,L,M,N || ∅ || ∅ | -------------------------------------------------- | a || b,c,d,f,g,h,i,j,k,n || e || l,m,o | | T13: 0 | U13: 31.0002 | V13: | ∅ || I,K || ∅ || A,D,G,N || B,C,E,F,H,J,L,M | --------------------------------------------------- | a || ∅ || b || c,j,k || d,e,f,g,h,i,l,m,n,o | | W13: 0.205 | X13: 4.242 | Y13: | ∅ || A,B,C,D,E,F,G,H,I,J,K,L,M,N || ∅ || ∅ || ∅ | ----------------------------------------------------- | a || c,d,e,f,g,h,i,j,k,l || b || m,n || o | | Z13: 0 | AA13: 29.6657
A14: =ROW(A9) -> 9 | B14: ABCDEFGHIJKLMN | C14: ABCDEFGHIJKLMN | D14: ⎛ ∅ ⎞⎛ A,B,C,D,E,F,G,H,I,J,K,L,M,N ⎞ ⎝ b ⎠⎝ a,c,d,e,f,g,h,i,j,k,l,m,n ⎠ | E14: 0 | F14: 0.0288 | G14: ⎛ A ⎞⎛ B,C,D,E,F,G,H,I,J,K,L,M,N ⎞ ⎝ a,c,e,g,i,k,m ⎠⎝ b,d,f,h,j,l,n ⎠ | H14: 0.073986 | I14: 30.0413 | J14: | H,I,J,L || F,G || A,B,C,D,E,K,M,N | ----------------------------------------- | a,g,n || e || b,c,d,f,h,i,j,k,l,m | | K14: 0.2224 | L14: 1.7803 | M14: | ∅ || A,B,C,D,E,F,G,H,I,J,K,L,M,N || ∅ | --------------------------------------------- | a || b,c,d,e,f,h,i,j,l,m || g,k,n | | N14: 0 | O14: 3.221 | P14: | ∅ || A,B,K,M,N || F || C,D,E,G,H,I,J,L | ------------------------------------------------ | a || d,l || ∅ || b,c,e,f,g,h,i,j,k,m,n | | Q14: 0.1857 | R14: 2.124 | S14: | A,B,C,D,E,F,G,H,I,J,K,L,M,N || ∅ || ∅ || ∅ | ------------------------------------------------ | d,e,f,g,h,i,j,k,l,m || a,c || b || n | | T14: 0 | U14: 3.5441 | V14: | ∅ || B,C,E,G,I,K,L,N || ∅ || D,H || A,F,J,M | ----------------------------------------------------- | a || c,d,e,f,h,i,j,k,l,m,n || b || g || ∅ | | W14: 0.1616 | X14: 3.0127 | Y14: | ∅ || A,B,C,D,E,F,G,H,I,J,K,L,M,N || ∅ || ∅ || ∅ | --------------------------------------------------- | a || d,e,f,g,h,i,j,k,l,m || b || c || n | | Z14: 0 | AA14: 12.3159
A15: =ROW(A10) -> 10 | B15: ABCDEFGHIJKLMN | C15: BCDEFGHIJKLMNO | D15: ⎛ ∅ ⎞⎛ A,B,C,D,E,F,G,H,I,J,K,L,M,N ⎞ ⎝ d ⎠⎝ b,c,e,f,g,h,i,j,k,l,m,n,o ⎠ | E15: 0 | F15: 0.2619 | G15: ⎛ A ⎞⎛ B,C,D,E,F,G,H,I,J,K,L,M,N ⎞ ⎝ b,d,f,h,j,l,n ⎠⎝ c,e,g,i,k,m,o ⎠ | H15: 0.062149 | I15: 30.0656 | J15: | C || A,B,D,F,G,H,I,J,L,M,N || E,K | --------------------------------------- | ∅ || b,d,e,g,h,i,j,l,m,n,o || c,f,k | | K15: 0.1603 | L15: 1.9461 | M15: | A,B,C,D,E,F,G,H,I,J,K,L,M,N || ∅ || ∅ | --------------------------------------------- | b,c,d,f,g,h,i,j,k,n || e || l,m,o | | N15: 0 | O15: 10.5549 | P15: | B,D,E,F,J,L,M,N || ∅ || A,C,G,H,I,K || ∅ | ---------------------------------------------- | b,d,h,j,l,m || f,n || c,g,i,k,o || e | | Q15: 0.2576 | R15: 1.9968 | S15: | A,B,C,D,E,F,G,H,I,J,K,L,M,N || ∅ || ∅ || ∅ | ------------------------------------------------ | b,c,e,g,h,i,j,k,l,o || d || f,m || n | | T15: 0 | U15: 16.3117 | V15: | B,F,I,J,L,N || A,C,D,E,G,K,M || ∅ || H || ∅ | --------------------------------------------------- | b,d,h,j,l || e,f,g,m,n || c,i,k || ∅ || o | | W15: 0.2785 | X15: 2.8672 | Y15: | A,B,C,D,E,F,G,H,I,J,K,L,M,N || ∅ || ∅ || ∅ || ∅ | --------------------------------------------------- | b,c,d,f,g,h,i,j,k,l || e || m || n || o | | Z15: 0 | AA15: 19.9534
A16: =ROW(A11) -> 11 | B16: ABCDEFGHIJKLMN | C16: BCDEFGHIJKLMN | D16: ⎛ ∅ ⎞⎛ A,B,C,D,E,F,G,H,I,J,K,L,M,N ⎞ ⎝ d ⎠⎝ b,c,e,f,g,h,i,j,k,l,m,n ⎠ | E16: 0 | F16: 0.2191 | G16: ⎛ A ⎞⎛ B,C,D,E,F,G,H,I,J,K,L,M,N ⎞ ⎝ c,e,g,i,k,m ⎠⎝ b,d,f,h,j,l,n ⎠ | H16: 0.072627 | I16: 30.0569 | J16: | E || A,B,F || C,D,G,H,I,J,K,L,M,N | ----------------------------------------- | e,f,m || d,l || b,c,g,h,i,j,k,n | | K16: 0.2504 | L16: 1.4065 | M16: | A,B,C,D,E,F,G,H,I,J,K,L,M,N || ∅ || ∅ | ----------------------------------------- | b,c,d,e,f,g,h,i,j,k,n || l || m | | N16: 0 | O16: 5.828 | P16: | G,K || D || E,J,N || A,B,C,F,H,I,L,M | ---------------------------------------- | f,n || j || c,g,k || b,d,e,h,i,l,m | | Q16: 0.2766 | R16: 1.6536 | S16: | A,B,C,D,E,F,G,H,I,J,K,L,M,N || ∅ || ∅ || ∅ | ---------------------------------------------- | b,c,d,f,h,i,j,k,l,m || e || g || n | | T16: 0 | U16: 9.2732 | V16: | ∅ || A,C,D || E,G || N || B,F,H,I,J,K,L,M | --------------------------------------------- | n || b,j || c,k || ∅ || d,e,f,g,h,i,l,m | | W16: 0.2633 | X16: 2.3647 | Y16: | A,B,C,D,E,F,G,H,I,J,K,L,M,N || ∅ || ∅ || ∅ || ∅ | ----------------------------------------------------- | c,d,g,h,i,j,k,l || b || e || f,m || n | | Z16: 0.003366 | AA16: 12.8843
A17: =ROW(A12) -> 12 | B17: ABCDEFGHIJKLMN | C17: ABDEGHJKMN | D17: ⎛ N ⎞⎛ A,B,C,D,E,F,G,H,I,J,K,L,M ⎞ ⎝ ∅ ⎠⎝ a,b,d,e,g,h,j,k,m,n ⎠ | E17: 0.0017 | F17: 2.0416 | G17: ⎛ A,B,C,E,F,G,H,I,J,K,L,M,N ⎞⎛ D ⎞ ⎝ a,b,d,e,g,h,j,k,m,n ⎠⎝ ∅ ⎠ | H17: 0.000761 | I17: 7.8791 | J17: | A,C,H,I,J,K,M || L || B,D,E,F,G,N | ------------------------------------- | a,e,g,h,m,n || d || b,j,k | | K17: 0.0632 | L17: 0.9189 | M17: | A,C,E,F,G,H,I,J,K,L,M,N || B || D | ------------------------------------- | a,b,d,e,g,h,j,k,m,n || ∅ || ∅ | | N17: 0.001555 | O17: 10.6022 | P17: | C,E,H,I,J,M || A,G,K,N || B,D,F || L | ---------------------------------------- | e,g,m,n || a,d,h || b,j,k || ∅ | | Q17: 0.0623 | R17: 1.1561 | S17: | A,C,E,F,G,H,I,J,K,M,N || B || D || L | ---------------------------------------- | a,b,d,e,g,h,j,k,m,n || ∅ || ∅ || ∅ | | T17: 0.003028 | U17: 22.6167 | V17: | H,L,N || A || ∅ || D,F,G,J,M || B,C,E,I,K | --------------------------------------------- | a || h || k || b,d,j || e,g,m,n | | W17: 0.0704 | X17: 1.6948 | Y17: | ∅ || A,C,E,F,G,H,I,M || B,J,K || D || L,N | --------------------------------------------- | a || b,d,e,g,h || j,k || ∅ || m,n | | Z17: 0.010463 | AA17: 30.1592
... A55: =ROW(A50) -> 50 | B55: BCDEFGJKLMNO | C55: BCDEFGHIJKLMNO | D55: ⎛ ∅ ⎞⎛ B,C,D,E,F,G,J,K,L,M,N,O ⎞ ⎝ d ⎠⎝ b,c,e,f,g,h,i,j,k,l,m,n,o ⎠ | E55: 0 | F55: 0.5873 | G55: ⎛ C ⎞⎛ B,D,E,F,G,J,K,L,M,N,O ⎞ ⎝ b,d,f,h,j,l,n ⎠⎝ c,e,g,i,k,m,o ⎠ | H55: 0.052068 | I55: 30.0245 | J55: | D,E,F,J,M,O || B,C,L,N || G,K | ----------------------------------------- | c,d,e,f,g,i,k,l,m,o || b,h,j,n || ∅ | | K55: 0.1501 | L55: 1.5097 | M55: | B,C,D,E,F,G,J,K,L,M,N,O || ∅ || ∅ | --------------------------------------- | b,c,d,e,f,g,h,i,j,k,n || l,o || m | | N55: 0 | O55: 8.0644 | P55: | ∅ || B,D,F,H,J,L,N || ∅ || ∅ | ---------------------------------------- | k || b,c,e,f,g,h,j,l,m,n || i,o || d | | Q55: 0.0662 | R55: 0.8484 | S55: | B,C,D,E,F,G,J,K,L,M,N,O || ∅ || ∅ || ∅ | -------------------------------------------- | c,d,e,g,h,i,j,k,l,o || b,m || f || n | | T55: 0 | U55: 6.137 | V55: | ∅ || B,C,F,J,K,L,M,N || D,E,O || G || ∅ | --------------------------------------------- | i || b,d,e,f,h,j,l,n || c,g,k,o || ∅ || m | | W55: 0.2064 | X55: 2.3773 | Y55: | B,C,D,E,F,G,J,K,L,M,N,O || ∅ || ∅ || ∅ || ∅ | ----------------------------------------------- | b,c,d,e,f,g,h,k,l,n || i || j || m || o | | Z55: 0 | AA55: 8.3983

Sheet 20A-Elementos
A1: Estado inicial | B1: 10000000000000000000
A2: Sistema: | B2: ABCDEFGHIJKLMNOPQRST
A3: Sistema Candidato: | B3: ABCDEFGHIJKLMNOPQRST | D3: PRUEBAS BIPARTICIONES | J3: PRUEBAS 3-PARTICIONES | P3: PRUEBAS 4-PARTICIONES | V3: PRUEBAS 5-PARTICIONES
B4: Subsistema | D4: QNodes | G4: Geometric | J4: QNodes | M4: Geometric | P4: QNodes | S4: Geometric | V4: QNodes | Y4: Geometric
A5: #Prueba | B5: Alcance o Purview (t+1) | C5: Mecanismo(t) | D5: Partición | E5: Pérdida | F5: Tiempo | G5: Partición | H5: Pérdida | I5: Tiempo | J5: Partición | K5: Pérdida | L5: Tiempo | M5: Partición | N5: Pérdida | O5: Tiempo | P5: Partición | Q5: Pérdida | R5: Tiempo | S5: Partición | T5: Pérdida | U5: Tiempo | V5: Partición | W5: Pérdida | X5: Tiempo | Y5: Partición | Z5: Pérdida | AA5: Tiempo
A6: =ROW(A1) -> 1 | B6: ABCDEFGHIJKLMNOPQRST | C6: ABCDEFGHIJKLMNOPQRST
A7: =ROW(A2) -> 2 | B7: ABCDEFGHIJKLMNOPQRST | C7: ABCDEFGHIJKLMNOPQRS
A8: =ROW(A3) -> 3 | B8: ABCDEFGHIJKLMNOPQRST | C8: BCDEFGHIJKLMNOPQRST
A9: =ROW(A4) -> 4 | B9: ABCDEFGHIJKLMNOPQRST | C9: BCDEFGHIJKLMNOPQRS
A10: =ROW(A5) -> 5 | B10: ABCDEFGHIJKLMNOPQRST | C10: ABDEGHJKMNPQST
A11: =ROW(A6) -> 6 | B11: ABCDEFGHIJKLMNOPQRST | C11: ACEGIKMOQS
A12: =ROW(A7) -> 7 | B12: ABCDEFGHIJKLMNOPQRST | C12: BDFHJLNPRT
A13: =ROW(A8) -> 8 | B13: ABCDEFGHIJKLMNOPQRS | C13: ABCDEFGHIJKLMNOPQRST
A14: =ROW(A9) -> 9 | B14: ABCDEFGHIJKLMNOPQRS | C14: ABCDEFGHIJKLMNOPQRS
A15: =ROW(A10) -> 10 | B15: ABCDEFGHIJKLMNOPQRS | C15: BCDEFGHIJKLMNOPQRST
A16: =ROW(A11) -> 11 | B16: ABCDEFGHIJKLMNOPQRS | C16: BCDEFGHIJKLMNOPQRS
A17: =ROW(A12) -> 12 | B17: ABCDEFGHIJKLMNOPQRS | C17: ABDEGHJKMNPQST
... A55: =ROW(A50) -> 50 | B55: BCDEFGJKLMNO | C55: BCDEFGHIJKLMNO

Sheet 22A-Elementos
A1: Estado inicial | B1: 1000000000000000000000
A2: Sistema: | B2: ABCDEFGHIJKLMNOPQRSTUV
A3: Sistema Candidato: | B3: ABCDEFGHIJKLMNOPQRSTUV | D3: PRUEBAS BIPARTICIONES | J3: PRUEBAS 3-PARTICIONES | P3: PRUEBAS 4-PARTICIONES | V3: PRUEBAS 5-PARTICIONES
B4: Subsistema | D4: QNodes | G4: Geometric | J4: QNodes | M4: Geometric | P4: QNodes | S4: Geometric | V4: QNodes | Y4: Geometric
A5: #Prueba | B5: Alcance o Purview (t+1) | C5: Mecanismo(t) | D5: Partición | E5: Pérdida | F5: Tiempo | G5: Partición | H5: Pérdida | I5: Tiempo | J5: Partición | K5: Pérdida | L5: Tiempo | M5: Partición | N5: Pérdida | O5: Tiempo | P5: Partición | Q5: Pérdida | R5: Tiempo | S5: Partición | T5: Pérdida | U5: Tiempo | V5: Partición | W5: Pérdida | X5: Tiempo | Y5: Partición | Z5: Pérdida | AA5: Tiempo
A6: =ROW(A1) -> 1 | B6: ABCDEFGHIJKLMNOPQRSTUV | C6: ABCDEFGHIJKLMNOPQRSTUV
A7: =ROW(A2) -> 2 | B7: ABCDEFGHIJKLMNOPQRSTUV | C7: ABCDEFGHIJKLMNOPQRSTU
A8: =ROW(A3) -> 3 | B8: ABCDEFGHIJKLMNOPQRSTUV | C8: BCDEFGHIJKLMNOPQRSTUV
A9: =ROW(A4) -> 4 | B9: ABCDEFGHIJKLMNOPQRSTUV | C9: BCDEFGHIJKLMNOPQRSTU
A10: =ROW(A5) -> 5 | B10: ABCDEFGHIJKLMNOPQRSTUV | C10: ABDEGHJKMNPQSTV
A11: =ROW(A6) -> 6 | B11: ABCDEFGHIJKLMNOPQRSTUV | C11: ACEGIKMOQSU
A12: =ROW(A7) -> 7 | B12: ABCDEFGHIJKLMNOPQRSTUV | C12: BDFHJLNPRTV
A13: =ROW(A8) -> 8 | B13: ABCDEFGHIJKLMNOPQRSTU | C13: ABCDEFGHIJKLMNOPQRSTUV
A14: =ROW(A9) -> 9 | B14: ABCDEFGHIJKLMNOPQRSTU | C14: ABCDEFGHIJKLMNOPQRSTU
A15: =ROW(A10) -> 10 | B15: ABCDEFGHIJKLMNOPQRSTU | C15: BCDEFGHIJKLMNOPQRSTUV
A16: =ROW(A11) -> 11 | B16: ABCDEFGHIJKLMNOPQRSTU | C16: BCDEFGHIJKLMNOPQRSTU
A17: =ROW(A12) -> 12 | B17: ABCDEFGHIJKLMNOPQRSTU | C17: ABDEGHJKMNPQSTV
... A55: =ROW(A50) -> 50 | B55: ACDEFGHIJKLMNOPQRST | C55: ACDEFGHIJKLMNOPQRST

Sheet 25A-Elementos 
A1: Estado inicial | B1: 1000000000000000000000000
A2: Sistema: | B2: ABCDEFGHIJKLMNOPQRSTUVWXY
A3: Sistema Candidato: | B3: ABCDEFGHIJKLMNOPQRSTUVWXY | D3: PRUEBAS BIPARTICIONES | J3: PRUEBAS 3-PARTICIONES | P3: PRUEBAS 4-PARTICIONES | V3: PRUEBAS 5-PARTICIONES
B4: Subsistema | D4: QNodes | G4: Geometric | J4: QNodes | M4: Geometric | P4: QNodes | S4: Geometric | V4: QNodes | Y4: Geometric
A5: #Prueba | B5: Alcance o Purview (t+1) | C5: Mecanismo(t) | D5: Partición | E5: Pérdida | F5: Tiempo | G5: Partición | H5: Pérdida | I5: Tiempo | J5: Partición | K5: Pérdida | L5: Tiempo | M5: Partición | N5: Pérdida | O5: Tiempo | P5: Partición | Q5: Pérdida | R5: Tiempo | S5: Partición | T5: Pérdida | U5: Tiempo | V5: Partición | W5: Pérdida | X5: Tiempo | Y5: Partición | Z5: Pérdida | AA5: Tiempo
A6: =ROW(A1) -> 1 | B6: ABCDEFGHIJKLMNOPQRSTUVWXY | C6: ABCDEFGHIJKLMNOPQRSTUVWXY
A7: =ROW(A2) -> 2 | B7: ABCDEFGHIJKLMNOPQRSTUVWXY | C7: ABCDEFGHIJKLMNOPQRSTUVWX
A8: =ROW(A3) -> 3 | B8: ABCDEFGHIJKLMNOPQRSTUVWXY | C8: BCDEFGHIJKLMNOPQRSTUVWXY
A9: =ROW(A4) -> 4 | B9: ABCDEFGHIJKLMNOPQRSTUVWXY | C9: BCDEFGHIJKLMNOPQRSTUVWX
A10: =ROW(A5) -> 5 | B10: ABCDEFGHIJKLMNOPQRSTUVWXY | C10: ABDEGHJKMNPQSTVWY
A11: =ROW(A6) -> 6 | B11: ABCDEFGHIJKLMNOPQRSTUVWXY | C11: ACEGIKMOQSUWY
A12: =ROW(A7) -> 7 | B12: ABCDEFGHIJKLMNOPQRSTUVWXY | C12: BDFHJLNPRTVX
A13: =ROW(A8) -> 8 | B13: ABCDEFGHIJKLMNOPQRSTUVWX | C13: ABCDEFGHIJKLMNOPQRSTUVWXY
A14: =ROW(A9) -> 9 | B14: ABCDEFGHIJKLMNOPQRSTUVWX | C14: ABCDEFGHIJKLMNOPQRSTUVWX
A15: =ROW(A10) -> 10 | B15: ABCDEFGHIJKLMNOPQRSTUVWX | C15: BCDEFGHIJKLMNOPQRSTUVWXY
A16: =ROW(A11) -> 11 | B16: ABCDEFGHIJKLMNOPQRSTUVWX | C16: BCDEFGHIJKLMNOPQRSTUVWX
A17: =ROW(A12) -> 12 | B17: ABCDEFGHIJKLMNOPQRSTUVWX | C17: ABDEGHJKMNPQSTVWY
... A55: =ROW(A50) -> 50 | B55: ACDEFGHIJKLMNOPQRSTVX | C55: ACDEFGHIJKLMNOPQRSTVX

Sheet Requerimientos
A1: Requerimientos iniciales
A2: Hacer las pruebas inicialespara BIPARTICIONES con las dos estrategias Qnodes y Geométrica.
A3: Al finalizar el proyecto tras diligenciar los datos en las hojas marcadas con los tipos de redes a analizar, resolver lo siguiente:
B4: 1, Buscar gráficos/representaciones que comparen de forma correcta las estrategias.
C5: a. Comparar para cada estrategia por subsistema su tiempo de ejecución de forma ordenada ascendentemente según número de elementos (tamaño). Esto se refiere solo a los resultados para K-particiones. Comparar por cada k-particion y pruebas comparado valores de perdida entre todas las particiones
C6: b. Comparar los valores de pérdida por cada subsistema. Se halla la misma k-particion?
C7: c. Una representación que permita apreciar estas variaciones en la pérdida (EMD) si se presenta entre las estrategias, tomando el valor de perdida de QNodes como referencia.

Sheet Graficos
A1: 10 A | N1: 10 A
A2: Prueba qnodes | B2: Alcance | C2: Mecanismo | D2: tamaño | E2: Perdida k=2 | F2: Perdida k=3 | G2: Perdida k=4 | H2: Perdida k=5 | I2: Tiempo_segundos k=2 | J2: Tiempo_segundos k=3 | K2: Tiempo_segundos k=4 | L2: Tiempo_segundos k=5 | N2: Prueba Geomip | O2: Alcance | P2: Mecanismo | Q2: tamaño | R2: Perdida k=2 | S2: Perdida k=3 | T2: Perdida k=4 | U2: Perdida k=5 | V2: Tiempo_segundos k=2 | W2: Tiempo_segundos k=3 | X2: Tiempo_segundos k=4 | Y2: Tiempo_segundos k=5
A3: 1 | B3: ACEGI | C3: ACEGI | D3: =LEN(B3)+LEN(C3) -> 10 | E3: 0.0508 | F3: 1.0273 | G3: 3.3828 | H3: 4.3984 | I3: 0.0718 | J3: 1.1154 | K3: 0.6364 | L3: 0.6302 | N3: 1 | O3: ACEGI | P3: ACEGI | Q3: =LEN(O3)+LEN(P3) -> 10 | R3: 0.472656 | S3: 0.953125 | T3: 1.433594 | U3: 1.917969 | V3: 1.5361 | W3: 2.0904 | X3: 4.8415 | Y3: 7.9711
A4: 2 | B4: ACEGI | C4: BDFHJ | D4: =LEN(B4)+LEN(C4) -> 10 | E4: 0.0117 | F4: 1.0303 | G4: 1.0615 | H4: 1.334 | I4: 0.0586 | J4: 0.9432 | K4: 0.527 | L4: 0.6407 | N4: 2 | O4: ACEGI | P4: BDFHJ | Q4: =LEN(O4)+LEN(P4) -> 10 | R4: 0.004883 | S4: 0.010742 | T4: 0.030273 | U4: 0.049805 | V4: 0.7382 | W4: 0.9255 | X4: 1.6895 | Y4: 2.3119
A5: 3 | B5: BDFHJ | C5: ACEGI | D5: =LEN(B5)+LEN(C5) -> 10 | E5: 0.0371 | F5: 0.4854 | G5: 1.4805 | H5: 2.0576 | I5: 0.0552 | J5: 0.7711 | K5: 0.53 | L5: 0.6446 | N5: 3 | O5: BDFHJ | P5: ACEGI | Q5: =LEN(O5)+LEN(P5) -> 10 | R5: 0.004883 | S5: 0.011719 | T5: 0.023438 | U5: 0.035156 | V5: 0.6779 | W5: 1.0507 | X5: 1.6948 | Y5: 2.3142
A6: 4 | B6: BDFHJ | C6: BDFHJ | D6: =LEN(B6)+LEN(C6) -> 10 | E6: 0.0254 | F6: 0.6709 | G6: 0.7637 | H6: 0.8594 | I6: 0.0551 | J6: 0.7876 | K6: 0.415 | L6: 0.6133 | N6: 4 | O6: BDFHJ | P6: BDFHJ | Q6: =LEN(O6)+LEN(P6) -> 10 | R6: 0.011719 | S6: 0.023438 | T6: 0.042969 | U6: 0.070312 | V6: 0.3059 | W6: 0.356 | X6: 0.5671 | Y6: 0.7631
A7: 5 | B7: ABDEGHJ | C7: ACEGI | D7: =LEN(B7)+LEN(C7) -> 12 | E7: 0.0371 | F7: 0.623 | G7: 0.7832 | H7: 0.8086 | I7: 0.0976 | J7: 0.0073 | K7: 0.2704 | L7: 0.449 | N7: 5 | O7: ABDEGHJ | P7: ACEGI | Q7: =LEN(O7)+LEN(P7) -> 12 | R7: 0.005859 | S7: 0.025391 | T7: 0.052734 | U7: 0.158203 | V7: 0.2202 | W7: 0.2468 | X7: 0.2279 | Y7: 0.2534
A8: 6 | B8: ABDEGHJ | C8: BDFHJ | D8: =LEN(B8)+LEN(C8) -> 12 | E8: 0.0254 | F8: 0.1113 | G8: 0.4346 | H8: 0.54 | I8: 0.096 | J8: 0.3657 | K8: 0.3611 | L8: 0.4338 | N8: 6 | O8: ABDEGHJ | P8: BDFHJ | Q8: =LEN(O8)+LEN(P8) -> 12 | R8: 0.015625 | S8: 0.040039 | T8: 0.077148 | U8: 0.12793 | V8: 0.0399 | W8: 0.0527 | X8: 0.0414 | Y8: 0.0574
A9: 7 | B9: ACEGI | C9: ABDEGHJ | D9: =LEN(B9)+LEN(C9) -> 12 | E9: 0.0273 | F9: 0.04 | G9: 0.1211 | H9: 0.2646 | I9: 0.0914 | J9: 0.4699 | K9: 0.3309 | L9: 0.321 | N9: 7 | O9: ACEGI | P9: ABDEGHJ | Q9: =LEN(O9)+LEN(P9) -> 12 | R9: 0.003906 | S9: 0.015625 | T9: 0.035156 | U9: 0.05957 | V9: 0.051 | W9: 0.0395 | X9: 0.0723 | Y9: 0.1001
A10: 8 | B10: BDFHJ | C10: ABDEGHJ | D10: =LEN(B10)+LEN(C10) -> 12 | E10: 0.1133 | F10: 2.8574 | G10: 2.4678 | H10: 3.9355 | I10: 0.0995 | J10: 0.8058 | K10: 0.5645 | L10: 0.5584 | N10: 8 | O10: BDFHJ | P10: ABDEGHJ | Q10: =LEN(O10)+LEN(P10) -> 12 | R10: 0.472656 | S10: 0.953125 | T10: 1.433594 | U10: 1.917969 | V10: 1.5776 | W10: 2.202 | X10: 5.6584 | Y10: 7.7408
A11: 9 | B11: BCDEFGHI | C11: ACEGI | D11: =LEN(B11)+LEN(C11) -> 13 | E11: 0.0244 | F11: 0.5166 | G11: 0.583 | H11: 1.083 | I11: 0.1639 | J11: 0.7133 | K11: 0.4859 | L11: 0.554 | N11: 9 | O11: BCDEFGHI | P11: ACEGI | Q11: =LEN(O11)+LEN(P11) -> 13 | R11: 0.004883 | S11: 0.024414 | T11: 0.043945 | U11: 0.071289 | V11: 0.9293 | W11: 1.082 | X11: 1.8993 | Y11: 2.1902
A12: 10 | B12: BCDEFGHI | C12: BDFHJ | D12: =LEN(B12)+LEN(C12) -> 13 | E12: 0.0117 | F12: 0.0391 | G12: 1.5986 | H12: 1.6484 | I12: 0.1464 | J12: 0.7383 | K12: 0.5174 | L12: 0.5825 | N12: 10 | O12: BCDEFGHI | P12: BDFHJ | Q12: =LEN(O12)+LEN(P12) -> 13 | R12: 0.004883 | S12: 0.011719 | T12: 0.023438 | U12: 0.035156 | V12: 0.634 | W12: 0.8582 | X12: 1.4871 | Y12: 2.2531
A13: 11 | B13: ACEGI | C13: BCDEFGHI | D13: =LEN(B13)+LEN(C13) -> 13 | E13: 0.0273 | F13: 0.5107 | G13: 0.666 | H13: 0.7949 | I13: 0.1215 | J13: 0.5766 | K13: 0.4595 | L13: 0.5314 | N13: 11 | O13: ACEGI | P13: BCDEFGHI | Q13: =LEN(O13)+LEN(P13) -> 13 | R13: 0.011719 | S13: 0.023438 | T13: 0.042969 | U13: 0.070312 | V13: 0.3313 | W13: 0.3762 | X13: 0.5741 | Y13: 0.7777
A14: 12 | B14: BDFHJ | C14: BCDEFGHI | D14: =LEN(B14)+LEN(C14) -> 13 | E14: 0.0117 | F14: 0.5352 | G14: 0.666 | H14: 0.6914 | I14: 0.1154 | J14: 0.6536 | K14: 0.4663 | L14: 0.4364 | N14: 12 | O14: BDFHJ | P14: BCDEFGHI | Q14: =LEN(O14)+LEN(P14) -> 13 | R14: 0.019531 | S14: 0.046875 | T14: 0.152344 | U14: 0.261719 | V14: 0.2098 | W14: 0.2229 | X14: 0.2633 | Y14: 0.1985
... A51: 49 | B51: ABCDEFGHIJ | C51: ABCDEFGHIJ | D51: =LEN(B51)+LEN(C51) -> 20 | E51: 0.4805 | F51: 0.1074 | G51: 0.125 | H51: 0.1465 | I51: 0.9596 | J51: 0.0659 | K51: 0.0625 | L51: 0.1263 | N51: 49 | O51: ABCDEFGHIJ | P51: ABCDEFGHIJ | Q51: =LEN(O51)+LEN(P51) -> 20 | R51: 0.024414 | S51: 0.049805 | T51: 0.081055 | U51: 0.092773 | V51: 0.0804 | W51: 0.0878 | X51: 0.093 | Y51: 0.1062
A53: 15B | N53: 15B
A54: Prueba qnodes | B54: Alcance | C54: Mecanismo | D54: tamaño | E54: Perdida k=2 | F54: Perdida k=3 | G54: Perdida k=4 | H54: Perdida k=5 | I54: Tiempo_segundos k=2 | J54: Tiempo_segundos k=3 | K54: Tiempo_segundos k=4 | L54: Tiempo_segundos k=5 | N54: Prueba Geomip | O54: Alcance | P54: Mecanismo | Q54: tamaño | R54: Perdida k=2 | S54: Perdida k=3 | T54: Perdida k=4 | U54: Perdida k=5 | V54: Tiempo_segundos k=2 | W54: Tiempo_segundos k=3 | X54: Tiempo_segundos k=4 | Y54: Tiempo_segundos k=5
A55: 1 | B55: ABCDEFGHIJKLMNO | C55: ABCDEFGHIJKLMNO | D55: =LEN(B55)+LEN(C55) -> 30 | E55: 0 | F55: 0.2308 | G55: 0.2172 | H55: 0.2452 | I55: 0.056 | J55: 3.5663 | K55: 4.2349 | L55: 4.0002 | N55: 1 | O55: ABCDEFGHIJKLMNO | P55: ABCDEFGHIJKLMNO | Q55: =LEN(O55)+LEN(P55) -> 30 | R55: 0.071169 | S55: 0 | T55: 0.008518 | U55: 0.004263 | V55: 30.0536 | W55: 22.4467 | X55: 30.5297 | Y55: 31.1088
A56: 2 | B56: ABCDEFGHIJKLMNO | C56: ABCDEFGHIJKLMN | D56: =LEN(B56)+LEN(C56) -> 29 | E56: 0 | F56: 0.2383 | G56: 0.1648 | H56: 0.1891 | I56: 0.0376 | J56: 2.0399 | K56: 2.3245 | L56: 2.636 | N56: 2 | O56: ABCDEFGHIJKLMNO | P56: ABCDEFGHIJKLMN | Q56: =LEN(O56)+LEN(P56) -> 29 | R56: 0.0806 | S56: 0 | T56: 0 | U56: 0 | V56: 30.0702 | W56: 11.2993 | X56: 17.7084 | Y56: 23.0212
A57: 3 | B57: ABCDEFGHIJKLMNO | C57: BCDEFGHIJKLMNO | D57: =LEN(B57)+LEN(C57) -> 29 | E57: 0 | F57: 0.1711 | G57: 0.2527 | H57: 0.2646 | I57: 0.2932 | J57: 2.2594 | K57: 2.215 | L57: 2.4276 | N57: 3 | O57: ABCDEFGHIJKLMNO | P57: BCDEFGHIJKLMNO | Q57: =LEN(O57)+LEN(P57) -> 29 | R57: 0.066363 | S57: 0 | T57: 0 | U57: 0 | V57: 30.0448 | W57: 10.2293 | X57: 16.6209 | Y57: 5.8181
A58: 4 | B58: ABCDEFGHIJKLMNO | C58: BCDEFGHIJKLMN | D58: =LEN(B58)+LEN(C58) -> 28 | E58: 0 | F58: 0.2414 | G58: 0.284 | H58: 0.2762 | I58: 0.2315 | J58: 1.577 | K58: 1.8129 | L58: 2.0749 | N58: 4 | O58: ABCDEFGHIJKLMNO | P58: BCDEFGHIJKLMN | Q58: =LEN(O58)+LEN(P58) -> 28 | R58: 0 | S58: 0 | T58: 0.003906 | U58: 0.004231 | V58: 29.2885 | W58: 1.9986 | X58: 3.3655 | Y58: 5.1702
A59: 5 | B59: ABCDEFGHIJKLMNO | C59: ABDEGHJKMN | D59: =LEN(B59)+LEN(C59) -> 25 | E59: 0.0013 | F59: 0.067 | G59: 0.0659 | H59: 0.0706 | I59: 2.2352 | J59: 1.0107 | K59: 1.2232 | L59: 1.4831 | N59: 5 | O59: ABCDEFGHIJKLMNO | P59: ABDEGHJKMN | Q59: =LEN(O59)+LEN(P59) -> 25 | R59: 0.000761 | S59: 0.001555 | T59: 0.003028 | U59: 0.01649 | V59: 2.3969 | W59: 3.1791 | X59: 17.0673 | Y59: 30.1593
A60: 6 | B60: ABCDEFGHIJKLMNO | C60: ACEGIKMO | D60: =LEN(B60)+LEN(C60) -> 23 | E60: 0.0044 | F60: 0.0487 | G60: 0.0947 | H60: 0.0971 | I60: 2.1588 | J60: 0.7993 | K60: 0.7342 | L60: 0.9462 | N60: 6 | O60: ABCDEFGHIJKLMNO | P60: ACEGIKMO | Q60: =LEN(O60)+LEN(P60) -> 23 | R60: 0.0001 | S60: 0.000436 | T60: 0.000775 | U60: 0.001184 | V60: 2.4167 | W60: 2.821 | X60: 3.316 | Y60: 4.289
A61: 7 | B61: ABCDEFGHIJKLMNO | C61: BDFHJLN | D61: =LEN(B61)+LEN(C61) -> 22 | E61: 0.0072 | F61: 0.0745 | G61: 0.0663 | H61: 0.1009 | I61: 2.5975 | J61: 0.7622 | K61: 0.892 | L61: 1.0787 | N61: 7 | O61: ABCDEFGHIJKLMNO | P61: BDFHJLN | Q61: =LEN(O61)+LEN(P61) -> 22 | R61: 0.000201 | S61: 0.000477 | T61: 0.001082 | U61: 0.001699 | V61: 1.1813 | W61: 1.323 | X61: 1.4854 | Y61: 1.8955
A62: 8 | B62: ABCDEFGHIJKLMN | C62: ABCDEFGHIJKLMNO | D62: =LEN(B62)+LEN(C62) -> 29 | E62: 0 | F62: 0.1963 | G62: 0.1946 | H62: 0.205 | I62: 0.0399 | J62: 3.3534 | K62: 3.6531 | L62: 4.242 | N62: 8 | O62: ABCDEFGHIJKLMN | P62: ABCDEFGHIJKLMNO | Q62: =LEN(O62)+LEN(P62) -> 29 | R62: 0.073146 | S62: 0 | T62: 0 | U62: 0 | V62: 30.0111 | W62: 19.6749 | X62: 31.0002 | Y62: 29.6657
A63: 9 | B63: ABCDEFGHIJKLMN | C63: ABCDEFGHIJKLMN | D63: =LEN(B63)+LEN(C63) -> 28 | E63: 0 | F63: 0.2224 | G63: 0.1857 | H63: 0.1616 | I63: 0.0288 | J63: 1.7803 | K63: 2.124 | L63: 3.0127 | N63: 9 | O63: ABCDEFGHIJKLMN | P63: ABCDEFGHIJKLMN | Q63: =LEN(O63)+LEN(P63) -> 28 | R63: 0.073986 | S63: 0 | T63: 0 | U63: 0 | V63: 30.0413 | W63: 3.221 | X63: 3.5441 | Y63: 12.3159
A64: 10 | B64: ABCDEFGHIJKLMN | C64: BCDEFGHIJKLMNO | D64: =LEN(B64)+LEN(C64) -> 28 | E64: 0 | F64: 0.1603 | G64: 0.2576 | H64: 0.2785 | I64: 0.2619 | J64: 1.9461 | K64: 1.9968 | L64: 2.8672 | N64: 10 | O64: ABCDEFGHIJKLMN | P64: BCDEFGHIJKLMNO | Q64: =LEN(O64)+LEN(P64) -> 28 | R64: 0.062149 | S64: 0 | T64: 0 | U64: 0 | V64: 30.0656 | W64: 10.5549 | X64: 16.3117 | Y64: 19.9534
A65: 11 | B65: ABCDEFGHIJKLMN | C65: BCDEFGHIJKLMN | D65: =LEN(B65)+LEN(C65) -> 27 | E65: 0 | F65: 0.2504 | G65: 0.2766 | H65: 0.2633 | I65: 0.2191 | J65: 1.4065 | K65: 1.6536 | L65: 2.3647 | N65: 11 | O65: ABCDEFGHIJKLMN | P65: BCDEFGHIJKLMN | Q65: =LEN(O65)+LEN(P65) -> 27 | R65: 0.072627 | S65: 0 | T65: 0 | U65: 0.003366 | V65: 30.0569 | W65: 5.828 | X65: 9.2732 | Y65: 12.8843
A66: 12 | B66: ABCDEFGHIJKLMN | C66: ABDEGHJKMN | D66: =LEN(B66)+LEN(C66) -> 24 | E66: 0.0017 | F66: 0.0632 | G66: 0.0623 | H66: 0.0704 | I66: 2.0416 | J66: 0.9189 | K66: 1.1561 | L66: 1.6948 | N66: 12 | O66: ABCDEFGHIJKLMN | P66: ABDEGHJKMN | Q66: =LEN(O66)+LEN(P66) -> 24 | R66: 0.000761 | S66: 0.001555 | T66: 0.003028 | U66: 0.010463 | V66: 7.8791 | W66: 10.6022 | X66: 22.6167 | Y66: 30.1592
... A104: 50 | B104: BCDEFGJKLMNO | C104: BCDEFGHIJKLMNO | D104: =LEN(B104)+LEN(C104) -> 26 | E104: 0 | F104: 0.1501 | G104: 0.0662 | H104: 0.2064 | I104: 0.5873 | J104: 1.5097 | K104: 0.8484 | L104: 2.3773 | N104: 50 | O104: BCDEFGJKLMNO | P104: BCDEFGHIJKLMNO | Q104: =LEN(O104)+LEN(P104) -> 26 | R104: 0.052068 | S104: 0 | T104: 0 | U104: 0 | V104: 30.0245 | W104: 8.0644 | X104: 6.137 | Y104: 8.3983
A106: 20 A | N106: 20 A
A107: Prueba qnodes | B107: Alcance | C107: Mecanismo | D107: tamaño | E107: Perdida k=2 | F107: Perdida k=3 | G107: Perdida k=4 | H107: Perdida k=5 | I107: Tiempo_segundos k=2 | J107: Tiempo_segundos k=3 | K107: Tiempo_segundos k=4 | L107: Tiempo_segundos k=5 | N107: Prueba Geomip | O107: Alcance | P107: Mecanismo | Q107: tamaño | R107: Perdida k=2 | S107: Perdida k=3 | T107: Perdida k=4 | U107: Perdida k=5 | V107: Tiempo_segundos k=2 | W107: Tiempo_segundos k=3 | X107: Tiempo_segundos k=4 | Y107: Tiempo_segundos k=5
A108: 1 | B108: ABCDEFGHIJKLMNOPQRST | C108: ABCDEFGHIJKLMNOPQRST | D108: =LEN(B108)+LEN(C108) -> 40 | N108: 1 | O108: ABCDEFGHIJKLMNOPQRST | P108: ABCDEFGHIJKLMNOPQRST | Q108: =LEN(O108)+LEN(P108) -> 40
A109: 2 | B109: ABCDEFGHIJKLMNOPQRST | C109: ABCDEFGHIJKLMNOPQRS | D109: =LEN(B109)+LEN(C109) -> 39 | N109: 2 | O109: ABCDEFGHIJKLMNOPQRST | P109: ABCDEFGHIJKLMNOPQRS | Q109: =LEN(O109)+LEN(P109) -> 39
A110: 3 | B110: ABCDEFGHIJKLMNOPQRST | C110: BCDEFGHIJKLMNOPQRST | D110: =LEN(B110)+LEN(C110) -> 39 | N110: 3 | O110: ABCDEFGHIJKLMNOPQRST | P110: BCDEFGHIJKLMNOPQRST | Q110: =LEN(O110)+LEN(P110) -> 39
A111: 4 | B111: ABCDEFGHIJKLMNOPQRST | C111: BCDEFGHIJKLMNOPQRS | D111: =LEN(B111)+LEN(C111) -> 38 | N111: 4 | O111: ABCDEFGHIJKLMNOPQRST | P111: BCDEFGHIJKLMNOPQRS | Q111: =LEN(O111)+LEN(P111) -> 38
A112: 5 | B112: ABCDEFGHIJKLMNOPQRST | C112: ABDEGHJKMNPQST | D112: =LEN(B112)+LEN(C112) -> 34 | N112: 5 | O112: ABCDEFGHIJKLMNOPQRST | P112: ABDEGHJKMNPQST | Q112: =LEN(O112)+LEN(P112) -> 34
A113: 6 | B113: ABCDEFGHIJKLMNOPQRST | C113: ACEGIKMOQS | D113: =LEN(B113)+LEN(C113) -> 30 | N113: 6 | O113: ABCDEFGHIJKLMNOPQRST | P113: ACEGIKMOQS | Q113: =LEN(O113)+LEN(P113) -> 30
A114: 7 | B114: ABCDEFGHIJKLMNOPQRST | C114: BDFHJLNPRT | D114: =LEN(B114)+LEN(C114) -> 30 | N114: 7 | O114: ABCDEFGHIJKLMNOPQRST | P114: BDFHJLNPRT | Q114: =LEN(O114)+LEN(P114) -> 30
A115: 8 | B115: ABCDEFGHIJKLMNOPQRS | C115: ABCDEFGHIJKLMNOPQRST | D115: =LEN(B115)+LEN(C115) -> 39 | N115: 8 | O115: ABCDEFGHIJKLMNOPQRS | P115: ABCDEFGHIJKLMNOPQRST | Q115: =LEN(O115)+LEN(P115) -> 39
...

Sheet GA2P15B
A22: =SUM(B2:B17) -> 0.042291667

Sheet G1.a.1 15B

Sheet GA1P10A

Sheet Datos2-10
A1: Prueba | B1: Alcance | C1: Mecanismo | D1: tamaño | E1: k | F1: Perdida k=2 | G1: Perdida k=3 | H1: Perdida k=4 | I1: Perdida k=5
A2: 1 | B2: ACEGI | C2: ACEGI | D2: 10 | E2: 2 | F2: 0,0508 | G2: 1,0273 | H2: 3.3828 | I2: 4.3984
A3: 2 | B3: ACEGI | C3: BDFHJ | D3: 10 | E3: 2 | F3: 0,0117 | G3: 1,0303 | H3: 1.0615 | I3: 1.334
A4: 3 | B4: BDFHJ | C4: ACEGI | D4: 10 | E4: 2 | F4: 0,0371 | G4: 0,4854 | H4: 1.4805 | I4: 2.0576
A5: 4 | B5: BDFHJ | C5: BDFHJ | D5: 10 | E5: 2 | F5: 0,0254 | G5: 0,6709 | H5: 0.7637 | I5: 0.8594

Sheet G1.a.1 10A

Sheet G1.a.1 10A geomip

Sheet G1.a.2 10A geomip

Sheet G1.a.1 15B geomip

Sheet G1.a.2 15B geomip

Sheet Datos1
A1: Prueba | B1: Alcance | C1: Mecanismo | D1: tamaño | E1: k | F1: Perdida | G1: Tiempo_segundos k=2 | H1: Tiempo_segundos k=3 | I1: Tiempo_segundos k=4 | J1: Tiempo_segundos k=5
A2: 1 | B2: ACEGI | C2: ACEGI | D2: 10 | E2: 2 | F2: 0,0508 | G2: 0.0718 | H2: 1.1154 | I2: 0.6364 | J2: 0.6302
A3: 2 | B3: ACEGI | C3: BDFHJ | D3: 10 | E3: 2 | F3: 0,0117 | G3: 0.0586 | H3: 0.9432 | I3: 0.527 | J3: 0.6407
A4: 3 | B4: BDFHJ | C4: ACEGI | D4: 10 | E4: 2 | F4: 0,0371 | G4: 0.0552 | H4: 0.7711 | I4: 0.53 | J4: 0.6446
A5: 4 | B5: BDFHJ | C5: BDFHJ | D5: 10 | E5: 2 | F5: 0,0254 | G5: 0.0551 | H5: 0.7876 | I5: 0.415 | J5: 0.6133
A6: 5 | B6: ABDEGHJ | C6: ACEGI | D6: 12 | E6: 2 | F6: 0,0371 | G6: 0.0976 | H6: 0.0073 | I6: 0.2704 | J6: 0.449
A7: 6 | B7: ABDEGHJ | C7: BDFHJ | D7: 12 | E7: 2 | F7: 0,0254 | G7: 0.096 | H7: 0.3657 | I7: 0.3611 | J7: 0.4338
A8: 7 | B8: ACEGI | C8: ABDEGHJ | D8: 12 | E8: 2 | F8: 0,0273 | G8: 0.0914 | H8: 0.4699 | I8: 0.3309 | J8: 0.321
A9: 8 | B9: BDFHJ | C9: ABDEGHJ | D9: 12 | E9: 2 | F9: 0,1133 | G9: 0.0995 | H9: 0.8058 | I9: 0.5645 | J9: 0.5584
A10: 9 | B10: BCDEFGHI | C10: ACEGI | D10: 13 | E10: 2 | F10: 0,0244 | G10: 0.1639 | H10: 0.7133 | I10: 0.4859 | J10: 0.554
A11: 10 | B11: BCDEFGHI | C11: BDFHJ | D11: 13 | E11: 2 | F11: 0,0117 | G11: 0.1464 | H11: 0.7383 | I11: 0.5174 | J11: 0.5825
A12: 11 | B12: ACEGI | C12: BCDEFGHI | D12: 13 | E12: 2 | F12: 0,0273 | G12: 0.1215 | H12: 0.5766 | I12: 0.4595 | J12: 0.5314
A13: 12 | B13: BDFHJ | C13: BCDEFGHI | D13: 13 | E13: 2 | F13: 0,0117 | G13: 0.1154 | H13: 0.6536 | I13: 0.4663 | J13: 0.4364
... A50: 49 | B50: ABCDEFGHIJ | C50: ABCDEFGHIJ | D50: 20 | E50: 2 | F50: 0,4805 | G50: 0.9596 | H50: 0.0659 | I50: 0.0625 | J50: 0.1263
